Running on sh05
# conda environments:
#
base                  *  /opt/conda
PGx_env                  /usr/users/rattrapagemehdibenghali/benghali_meh/.conda/envs/PGx_env
PGx_env_37               /usr/users/rattrapagemehdibenghali/benghali_meh/.conda/envs/PGx_env_37

Read cache from caches/data_facebook/bart-large_CADEC_word.pt.
max_len_a:1.6, max_len:10
In total 1 datasets:
	train has 5340 instances.

The number of tokens in tokenizer  50265
50266 50271
DataBundle do NOT have DataSet named test. It should be one of dict_keys(['train']).
Traceback (most recent call last):
  File "./BARTNER/train.py", line 189, in <module>
    callbacks.append(FitlogCallback(data_bundle.get_dataset('test'), raise_threshold=0.04,
  File "/usr/users/rattrapagemehdibenghali/benghali_meh/.local/lib/python3.8/site-packages/fastNLP/io/data_bundle.py", line 76, in get_dataset
    raise KeyError(error_msg)
KeyError: "DataBundle do NOT have DataSet named test. It should be one of dict_keys(['train'])."
